<mujoco model="ant_with_ball">
  <compiler angle="degree" coordinate="local" inertiafromgeom="true"/>
  <option integrator="RK4" timestep="0.01" gravity="0 0 -9.81"/>

  <custom>
    <numeric data="0.0 0.0 0.55 1.0 0.0 0.0 0.0 0.0 1.0 0.0 -1.0 0.0 -1.0 0.0 1.0" name="init_qpos"/>
  </custom>
  <default>
    <joint armature="1" damping="1" limited="true"/>
    <geom conaffinity="0" condim="3" density="5.0" friction="1 0.5 0.5" margin="0.01" rgba="0.8 0.6 0.4 1"/>
  </default>
  <asset>
      <texture type="skybox" builtin="gradient" rgb1=".4 .5 .6" rgb2="0 0 0" width="100" height="100"/>
      <texture builtin="flat" height="1278" name="texgeom" random="0.01" rgb1="0.9 0.9 0.9" rgb2="0.9 0.9 0.9" type="cube" width="127"/>
      <texture builtin="checker" height="100" name="texplane" rgb1="0 0 0" rgb2="0.8 0.8 0.8" type="2d" width="100"/>
      <material name="MatPlane" reflectance="0.5" shininess="1" specular="1" texrepeat="22 22" texture="texplane"/>
      <material name="geom" texture="texgeom" texuniform="true"/>
  </asset>
  <worldbody>
    <!-- <camera name="top_view" mode="fixed" pos="0 0 10" xyaxes="1 0 0 0 1 0"/> -->
    <!-- <camera name="top_view" mode="fixed" pos="0 0 50" xyaxes="1 0 0 0 1 0"/> -->
    <light cutoff="100" diffuse="1 1 1" dir="-0 0 -1.3" directional="true" exponent="1" pos="0 0 1.3" specular=".1 .1 .1"/>
    <geom conaffinity="1" condim="3" name="floor" pos="0 0 0" rgba="0.8 0.9 0.8 1" size="140 140 140" type="plane" material="MatPlane"/>
    
    <body name="falling_ball" pos="0 0 2">
      <joint name="falling_ball_joint" type="free" limited="false" damping="0.1"/>
      <geom name="falling_ball_geom" conaffinity="1" type="sphere" size="0.3" density="10" rgba="0.8 0.0 0.0 1" solref="0.01 0.1" solimp="0.1 0.95 0.001"/>
    </body>

    <geom name="safety_marker" type="sphere" size="0.5" pos="0 0 100" rgba="0 1 0 0.5" contype="0" conaffinity="0"/>

    <body name="torso" pos="0 0 0.75">
      <camera name="track_camera" mode="trackcom" pos="0 -7.5 1.5" xyaxes="1 0 0 0 0.10 1"/>

      <geom name="torso_geom" pos="0 0 0" size="0.2" type="sphere" rgba="0.8 0.0 0.0 1.0"/>
      <joint armature="0" damping="0" limited="false" margin="0.01" name="root" pos="0 0 0" type="free"/>
      <geom name="axis_geom" pos="0 0 0.4" size="0.05 0.4" type="cylinder" conaffinity="0"  rgba="0.0 0.8 0.0 1.0"/>
      <geom name="plate_geom" pos="0 0 0.8" size="0.9 0.9 0.05" type="box" rgba="0.0 0.0 1.0 1.0"/>
        
      <body name="front_left_leg" pos="0 0 0">
        <geom fromto="0.0 0.0 0.0 0.2 0.2 0.0" name="aux_1_geom" size="0.08" type="capsule" rgba="0.8 0.6 .4 1" />
        <body name="aux_1" pos="0.2 0.2 0">
          <joint axis="0 0 1" name="hip_1" pos="0.0 0.0 0.0" range="-30 30" type="hinge"/>
          <geom fromto="0.0 0.0 0.0 0.2 0.2 0.0" name="left_leg_geom" size="0.08" type="capsule" rgba="0.8 0.6 .4 1" />
          <body pos="0.2 0.2 0">
            <joint axis="-1 1 0" name="ankle_1" pos="0.0 0.0 0.0" range="30 70" type="hinge"/>
            <geom fromto="0.0 0.0 0.0 0.4 0.4 0.0" name="left_ankle_geom" size="0.08" type="capsule" rgba="0.8 0.6 .4 1" />
          </body>
        </body>
      </body>
      
      <body name="front_right_leg" pos="0 0 0">
        <geom fromto="0.0 0.0 0.0 -0.2 0.2 0.0" name="aux_2_geom" size="0.08" type="capsule" rgba="0.8 0.6 .4 1"  />
        <body name="aux_2" pos="-0.2 0.2 0">
          <joint axis="0 0 1" name="hip_2" pos="0.0 0.0 0.0" range="-30 30" type="hinge"/>
          <geom fromto="0.0 0.0 0.0 -0.2 0.2 0.0" name="right_leg_geom" size="0.08" type="capsule" rgba="0.8 0.6 .4 1" />
          <body pos="-0.2 0.2 0">
            <joint axis="1 1 0" name="ankle_2" pos="0.0 0.0 0.0" range="-70 -30" type="hinge"/>
            <geom fromto="0.0 0.0 0.0 -0.4 0.4 0.0" name="right_ankle_geom" size="0.08" type="capsule" rgba="0.8 0.6 .4 1" />
          </body>
        </body>
      </body>
      
      <body name="back_leg" pos="0 0 0">
        <geom fromto="0.0 0.0 0.0 -0.2 -0.2 0.0" name="aux_3_geom" size="0.08" type="capsule" rgba="0.8 0.6 .4 1"  />
        <body name="aux_3" pos="-0.2 -0.2 0">
          <joint axis="0 0 1" name="hip_3" pos="0.0 0.0 0.0" range="-30 30" type="hinge"/>
          <geom fromto="0.0 0.0 0.0 -0.2 -0.2 0.0" name="back_leg_geom" size="0.08" type="capsule" rgba="0.8 0.6 .4 1" />
          <body pos="-0.2 -0.2 0">
            <joint axis="-1 1 0" name="ankle_3" pos="0.0 0.0 0.0" range="-70 -30" type="hinge"/>
            <geom fromto="0.0 0.0 0.0 -0.4 -0.4 0.0" name="third_ankle_geom" size="0.08" type="capsule" rgba="0.8 0.6 .4 1" />
          </body>
        </body>
      </body>
      
      <body name="right_back_leg" pos="0 0 0">
        <geom fromto="0.0 0.0 0.0 0.2 -0.2 0.0" name="aux_4_geom" size="0.08" type="capsule" rgba="0.8 0.6 .4 1" />
        <body name="aux_4" pos="0.2 -0.2 0">
          <joint axis="0 0 1" name="hip_4" pos="0.0 0.0 0.0" range="-30 30" type="hinge"/>
          <geom fromto="0.0 0.0 0.0 0.2 -0.2 0.0" name="rightback_leg_geom" size="0.08" type="capsule" rgba="0.8 0.6 .4 1" />
          <body pos="0.2 -0.2 0">
            <joint axis="1 1 0" name="ankle_4" pos="0.0 0.0 0.0" range="30 70" type="hinge"/>
            <geom fromto="0.0 0.0 0.0 0.4 -0.4 0.0" name="fourth_ankle_geom" size="0.08" type="capsule" rgba="0.8 0.6 .4 1" />
          </body>
        </body>
      </body>
    </body>
  </worldbody>
  
  <actuator>
    <motor ctrllimited="true" ctrlrange="-1.0 1.0" joint="hip_4"   gear="80"/>
    <motor ctrllimited="true" ctrlrange="-1.0 1.0" joint="ankle_4" gear="80"/>
    <motor ctrllimited="true" ctrlrange="-1.0 1.0" joint="hip_1"   gear="80"/>
    <motor ctrllimited="true" ctrlrange="-1.0 1.0" joint="ankle_1" gear="80"/>
    <motor ctrllimited="true" ctrlrange="-1.0 1.0" joint="hip_2"   gear="80"/>
    <motor ctrllimited="true" ctrlrange="-1.0 1.0" joint="ankle_2" gear="80"/>
    <motor ctrllimited="true" ctrlrange="-1.0 1.0" joint="hip_3"   gear="80"/>
    <motor ctrllimited="true" ctrlrange="-1.0 1.0" joint="ankle_3" gear="80"/>
  </actuator>
</mujoco>
